{"name": "Test - Validar la edicion de una minuta", "status": "broken", "statusDetails": {"message": "urllib3.exceptions.MaxRetryError: HTTPConnectionPool(host='localhost', port=57303): Max retries exceeded with url: /session/23c8d7ddc58bd87ace89c24ed6e4a15c/screenshot (Caused by NewConnectionError('<urllib3.connection.HTTPConnection object at 0x7d4b224cea60>: Failed to establish a new connection: [Errno 111] Connection refused'))\n", "trace": "  File \"/home/ipadula/Copernico/venv/lib/python3.8/site-packages/behave/runner.py\", line 545, in run_hook\n    self.hooks[name](context, *args)\n  File \"features/environment.py\", line 56, in after_step\n    pm.hook.after_step(context=context, step=step)\n  File \"/home/ipadula/Copernico/venv/lib/python3.8/site-packages/pluggy/_hooks.py\", line 265, in __call__\n    return self._hookexec(self.name, self.get_hookimpls(), kwargs, firstresult)\n  File \"/home/ipadula/Copernico/venv/lib/python3.8/site-packages/pluggy/_manager.py\", line 80, in _hookexec\n    return self._inner_hookexec(hook_name, methods, kwargs, firstresult)\n  File \"/home/ipadula/Copernico/venv/lib/python3.8/site-packages/pluggy/_callers.py\", line 60, in _multicall\n    return outcome.get_result()\n  File \"/home/ipadula/Copernico/venv/lib/python3.8/site-packages/pluggy/_result.py\", line 60, in get_result\n    raise ex[1].with_traceback(ex[2])\n  File \"/home/ipadula/Copernico/venv/lib/python3.8/site-packages/pluggy/_callers.py\", line 39, in _multicall\n    res = hook_impl.function(*args)\n  File \"/home/ipadula/Avla/helper/plugins/SeleniumPlugin.py\", line 187, in after_step\n    allure.attach(context.browser.get_screenshot_as_png(), name=\"screenshot\", attachment_type=AttachmentType.PNG)\n  File \"/home/ipadula/Copernico/venv/lib/python3.8/site-packages/selenium/webdriver/remote/webdriver.py\", line 927, in get_screenshot_as_png\n    return b64decode(self.get_screenshot_as_base64().encode(\"ascii\"))\n  File \"/home/ipadula/Copernico/venv/lib/python3.8/site-packages/selenium/webdriver/remote/webdriver.py\", line 938, in get_screenshot_as_base64\n    return self.execute(Command.SCREENSHOT)[\"value\"]\n  File \"/home/ipadula/Copernico/venv/lib/python3.8/site-packages/selenium/webdriver/remote/webdriver.py\", line 438, in execute\n    response = self.command_executor.execute(driver_command, params)\n  File \"/home/ipadula/Copernico/venv/lib/python3.8/site-packages/selenium/webdriver/remote/remote_connection.py\", line 290, in execute\n    return self._request(command_info[0], url, body=data)\n  File \"/home/ipadula/Copernico/venv/lib/python3.8/site-packages/selenium/webdriver/remote/remote_connection.py\", line 311, in _request\n    response = self._conn.request(method, url, body=body, headers=headers)\n  File \"/home/ipadula/Copernico/venv/lib/python3.8/site-packages/urllib3/request.py\", line 74, in request\n    return self.request_encode_url(\n  File \"/home/ipadula/Copernico/venv/lib/python3.8/site-packages/urllib3/request.py\", line 96, in request_encode_url\n    return self.urlopen(method, url, **extra_kw)\n  File \"/home/ipadula/Copernico/venv/lib/python3.8/site-packages/urllib3/poolmanager.py\", line 376, in urlopen\n    response = conn.urlopen(method, u.request_uri, **kw)\n  File \"/home/ipadula/Copernico/venv/lib/python3.8/site-packages/urllib3/connectionpool.py\", line 813, in urlopen\n    return self.urlopen(\n  File \"/home/ipadula/Copernico/venv/lib/python3.8/site-packages/urllib3/connectionpool.py\", line 813, in urlopen\n    return self.urlopen(\n  File \"/home/ipadula/Copernico/venv/lib/python3.8/site-packages/urllib3/connectionpool.py\", line 813, in urlopen\n    return self.urlopen(\n  File \"/home/ipadula/Copernico/venv/lib/python3.8/site-packages/urllib3/connectionpool.py\", line 785, in urlopen\n    retries = retries.increment(\n  File \"/home/ipadula/Copernico/venv/lib/python3.8/site-packages/urllib3/util/retry.py\", line 592, in increment\n    raise MaxRetryError(_pool, url, error or ResponseError(cause))\n"}, "steps": [{"name": "Given Estoy en el ingreso al portal sin loguearme", "status": "passed", "attachments": [{"name": "screenshot", "source": "c590e5e8-e42f-4ee3-8f09-b451164907bf-attachment.png", "type": "image/png"}], "start": 1750275165303, "stop": 1750275169390}, {"name": "When Me logueo con las credenciales \"admin\"", "status": "passed", "attachments": [{"name": "screenshot", "source": "709cca2e-3720-4c9f-ba5b-05b85653731a-attachment.png", "type": "image/png"}], "start": 1750275169390, "stop": 1750275176611}, {"name": "And Despliego la seccion \"Risk Management\"", "status": "broken", "statusDetails": {"message": "urllib3.exceptions.MaxRetryError: HTTPConnectionPool(host='localhost', port=57303): Max retries exceeded with url: /session/23c8d7ddc58bd87ace89c24ed6e4a15c/screenshot (Caused by NewConnectionError('<urllib3.connection.HTTPConnection object at 0x7d4b224cea60>: Failed to establish a new connection: [Errno 111] Connection refused'))\n", "trace": "  File \"/home/ipadula/Copernico/venv/lib/python3.8/site-packages/behave/runner.py\", line 545, in run_hook\n    self.hooks[name](context, *args)\n  File \"features/environment.py\", line 56, in after_step\n    pm.hook.after_step(context=context, step=step)\n  File \"/home/ipadula/Copernico/venv/lib/python3.8/site-packages/pluggy/_hooks.py\", line 265, in __call__\n    return self._hookexec(self.name, self.get_hookimpls(), kwargs, firstresult)\n  File \"/home/ipadula/Copernico/venv/lib/python3.8/site-packages/pluggy/_manager.py\", line 80, in _hookexec\n    return self._inner_hookexec(hook_name, methods, kwargs, firstresult)\n  File \"/home/ipadula/Copernico/venv/lib/python3.8/site-packages/pluggy/_callers.py\", line 60, in _multicall\n    return outcome.get_result()\n  File \"/home/ipadula/Copernico/venv/lib/python3.8/site-packages/pluggy/_result.py\", line 60, in get_result\n    raise ex[1].with_traceback(ex[2])\n  File \"/home/ipadula/Copernico/venv/lib/python3.8/site-packages/pluggy/_callers.py\", line 39, in _multicall\n    res = hook_impl.function(*args)\n  File \"/home/ipadula/Avla/helper/plugins/SeleniumPlugin.py\", line 187, in after_step\n    allure.attach(context.browser.get_screenshot_as_png(), name=\"screenshot\", attachment_type=AttachmentType.PNG)\n  File \"/home/ipadula/Copernico/venv/lib/python3.8/site-packages/selenium/webdriver/remote/webdriver.py\", line 927, in get_screenshot_as_png\n    return b64decode(self.get_screenshot_as_base64().encode(\"ascii\"))\n  File \"/home/ipadula/Copernico/venv/lib/python3.8/site-packages/selenium/webdriver/remote/webdriver.py\", line 938, in get_screenshot_as_base64\n    return self.execute(Command.SCREENSHOT)[\"value\"]\n  File \"/home/ipadula/Copernico/venv/lib/python3.8/site-packages/selenium/webdriver/remote/webdriver.py\", line 438, in execute\n    response = self.command_executor.execute(driver_command, params)\n  File \"/home/ipadula/Copernico/venv/lib/python3.8/site-packages/selenium/webdriver/remote/remote_connection.py\", line 290, in execute\n    return self._request(command_info[0], url, body=data)\n  File \"/home/ipadula/Copernico/venv/lib/python3.8/site-packages/selenium/webdriver/remote/remote_connection.py\", line 311, in _request\n    response = self._conn.request(method, url, body=body, headers=headers)\n  File \"/home/ipadula/Copernico/venv/lib/python3.8/site-packages/urllib3/request.py\", line 74, in request\n    return self.request_encode_url(\n  File \"/home/ipadula/Copernico/venv/lib/python3.8/site-packages/urllib3/request.py\", line 96, in request_encode_url\n    return self.urlopen(method, url, **extra_kw)\n  File \"/home/ipadula/Copernico/venv/lib/python3.8/site-packages/urllib3/poolmanager.py\", line 376, in urlopen\n    response = conn.urlopen(method, u.request_uri, **kw)\n  File \"/home/ipadula/Copernico/venv/lib/python3.8/site-packages/urllib3/connectionpool.py\", line 813, in urlopen\n    return self.urlopen(\n  File \"/home/ipadula/Copernico/venv/lib/python3.8/site-packages/urllib3/connectionpool.py\", line 813, in urlopen\n    return self.urlopen(\n  File \"/home/ipadula/Copernico/venv/lib/python3.8/site-packages/urllib3/connectionpool.py\", line 813, in urlopen\n    return self.urlopen(\n  File \"/home/ipadula/Copernico/venv/lib/python3.8/site-packages/urllib3/connectionpool.py\", line 785, in urlopen\n    retries = retries.increment(\n  File \"/home/ipadula/Copernico/venv/lib/python3.8/site-packages/urllib3/util/retry.py\", line 592, in increment\n    raise MaxRetryError(_pool, url, error or ResponseError(cause))\n"}, "start": 1750275176611, "stop": 1750275176697}, {"name": "And Me dirijo a la seccion \"Approval Minutes\"", "status": "skipped", "start": 1750275176706, "stop": 1750275176706}, {"name": "And Presiono el boton \"New\"", "status": "skipped", "start": 1750275176706, "stop": 1750275176706}], "start": 1750275164037, "stop": 1750275176706, "uuid": "037f7600-b196-40ff-a763-fbdba87c661f", "historyId": "6b06e09756782370e1accb0b28f0f99c", "fullName": "Risks: Test - Validar la edicion de una minuta", "labels": [{"name": "severity", "value": "normal"}, {"name": "tag", "value": "edit_minute"}, {"name": "tag", "value": "regresion"}, {"name": "tag", "value": "risks"}, {"name": "feature", "value": "Risks"}, {"name": "framework", "value": "behave"}, {"name": "language", "value": "cpython3"}]}